Workbook

Sheet Hướng dẫn
B1: BỘ TEMPLATE BÁO CÁO CÔNG VIỆC THEO TUẦN VÀ THÁNG
B2: Áp dụng cho 4 phòng ban: Marketing Content, Tài chính - Thu mua, Program Event, Nhân sự
B4: 1. MỤC ĐÍCH: MỖI BÁO CÁO TRẢ LỜI 5 CÂU HỎI
B5: Câu hỏi | C5: Nằm ở phần nào trong báo cáo
B6: Làm gì? | C6: Cột Task trong bảng công việc, bảng kế hoạch
B7: Ai làm? | C7: Cột Owner, Vai trò và bảng RACI
B8: Khi nào? | C8: Cột Deadline và Status
B9: Tới đâu? | C9: Cột % HT, bảng KPI, điểm đánh giá
B10: Còn tồn gì? | C10: Bảng task tồn đọng (có lý do, giải pháp, deadline mới) và bảng vấn đề, đề xuất
B12: 2. DANH SÁCH SHEET
B13: Sheet | C13: Nội dung
B14: Danh mục | C14: Danh sách chọn (Status, Ưu tiên, Vai trò từng phòng) và ngưỡng đánh giá KPI, xếp loại. Sửa tại đây để áp dụng cho toàn bộ file
B15: [Phòng ban] - Tuần | C15: Báo cáo tuần: thông tin chung, tổng quan, bảng công việc, RACI, task tồn, task tuần sau, vấn đề và đề xuất, KPI tuần
B16: [Phòng ban] - Tháng | C16: Báo cáo tháng: tổng quan, KPI, điểm đánh giá, task hoàn thành / tồn / hủy, root cause, đóng góp thành viên, kế hoạch tháng sau, đề xuất
B17: Phòng ban có sẵn | C17: Marketing Content, Tài chính Thu mua, Program Event, Nhân sự (mỗi phòng 1 sheet Tuần và 1 sheet Tháng, KPI và vai trò đã được gợi ý theo đặc thù)
B19: 3. CÁCH SỬ DỤNG
B20: Bước 1 | C20: Nhân bản (Move or Copy) sheet của phòng ban cho mỗi kỳ báo cáo, đặt tên theo tuần hoặc tháng, ví dụ: Marketing Content - Tuần 42
B21: Bước 2 | C21: Điền phần Thông tin chung. Chỉ cần nhập ngày Thứ 2 ở sheet Tuần, ngày Chủ nhật tự tính
B22: Bước 3 | C22: Xóa dòng ví dụ (dòng số 1 mỗi bảng) rồi nhập dữ liệu thật. Mỗi task có đúng 1 Owner, có Deadline và Status
B23: Bước 4 | C23: Task chưa xong phải đưa vào bảng Task tồn đọng với lý do, giải pháp và deadline mới
B24: Bước 5 | C24: Nhập Target và Thực tế cho từng KPI. % HT và Trạng thái tự tính. Có thể đổi tên KPI cho phù hợp
B25: Bước 6 | C25: Kiểm tra checklist ở mục 6 rồi nộp đúng hạn
B27: 4. QUY ƯỚC Ô VÀ ĐỊNH DẠNG
B28: Nền vàng nhạt | C28: Ô nhập thông tin chung (phòng ban, người báo cáo, tuần/tháng...)
B29: Nền xám nhạt | C29: Ô công thức tự tính (% HT, Trạng thái, Đúng hạn, tổng quan...). Không gõ đè
B30: Ô trắng | C30: Ô nhập dữ liệu. Các cột có mũi tên là danh sách chọn, vẫn có thể gõ giá trị khác
B31: Chữ đỏ ở Deadline | C31: Deadline đã qua nhưng Status chưa phải Done
B32: KPI nhập số thuần | C32: KPI đơn vị % nhập 95 cho 95%. Cột Chiều đạt cho biết KPI cao hơn là tốt (lead, doanh thu) hay thấp hơn là tốt (CPL, công nợ quá hạn)
B33: Status | C33: Done: hoàn thành | In Progress: đang làm | Blocked: đang vướng | Pending: chờ xử lý | Overdue: trễ hạn
B35: 5. CHU KỲ BÁO CÁO CHUẨN
B36: Thời điểm | C36: Hoạt động
B37: Thứ 2 | C37: Nhận task tuần (Weekly Planning)
B38: Hằng ngày, 9:00 | C38: Daily standup 15 phút: hôm nay làm gì, có vướng gì
B39: Thứ 4 | C39: Check-in giữa tuần 15 phút
B40: Thứ 6, 16:00 | C40: Weekly review 60 phút, trình bày báo cáo tuần
B41: Thứ 6, 17:00 | C41: Hạn nộp báo cáo tuần
B42: Ngày 3 hằng tháng | C42: Hạn nộp báo cáo tháng của tháng trước
B43: Ngày 5 hằng tháng | C43: Monthly review 2 giờ, toàn công ty và liên phòng ban
B44: Hằng quý | C44: Họp OKR 4 giờ, thiết lập lại mục tiêu
B46: 6. CHECKLIST TRƯỚC KHI NỘP
...

Sheet Marketing Content - Tuần
A1: BÁO CÁO CÔNG VIỆC TUẦN - MARKETING CONTENT
A2: Ô nền vàng: nhập thông tin chung. Ô nền xám: công thức tự tính, không sửa. Dòng số 1 của mỗi bảng là dòng ví dụ, ghi đè hoặc xóa khi dùng.
A4: A. THÔNG TIN CHUNG
B5: Phòng ban | C5: Marketing Content | E5: Tuần số | G5: 41
B6: Từ ngày (Thứ 2) | C6: 46300 | E6: Đến ngày (Chủ nhật) | G6: =C6+6 -> 46306
B7: Người báo cáo | E7: Người nhận
B8: Hạn nộp | C8: Thứ 6, 17:00 | E8: Ngày nộp thực tế
A10: B. TỔNG QUAN TUẦN
B11: Tổng task | C11: Done | D11: In Progress | E11: Blocked | F11: Pending | G11: Overdue | H11: % hoàn thành trung bình | I11: Tỷ lệ task Done
B12: =COUNTA(B16:B30) -> 1 | C12: =COUNTIF(F16:F30,"Done") -> 1 | D12: =COUNTIF(F16:F30,"In Progress") -> 0 | E12: =COUNTIF(F16:F30,"Blocked") -> 0 | F12: =COUNTIF(F16:F30,"Pending") -> 0 | G12: =COUNTIF(F16:F30,"Overdue") -> 0 | H12: =IFERROR(AVERAGE(G16:G30),"") -> 1 | I12: =IFERROR(C12/B12,"") -> 1
A14: C. BẢNG CÔNG VIỆC TRONG TUẦN
A15: # | B15: Task | C15: Vai trò | D15: Owner | E15: Deadline | F15: Status | G15: % HT | H15: Kết quả / Ghi chú
A16: 1 | B16: Viết 8 bài content tháng 10 | C16: Content Writer | D16: A | E16: 46304 | F16: Done | G16: 1 | H16: Đăng đủ 8 bài
A17: 2
A18: 3
A19: 4
A20: 5
A21: 6
A22: 7
A23: 8
A24: 9
A25: 10
A26: 11
A27: 12
A28: 13
... A30: 15
B31: Status: Done (hoàn thành) / In Progress (đang làm) / Blocked (đang vướng) / Pending (chờ xử lý) / Overdue (trễ hạn). Deadline quá hạn mà chưa Done sẽ hiện chữ đỏ.
A33: D. VAI TRÒ VÀ TRÁCH NHIỆM (RACI) - CHO TASK QUAN TRỌNG
A34: # | B34: Task | C34: R - Người làm | D34: A - Người duyệt / chịu trách nhiệm cuối | E34: C - Người tư vấn | G34: I - Người nhận thông tin | I34: Ghi chú
A35: 1 | B35: Viết content | C35: Content Writer | D35: Marketing Lead | E35: Sales | G35: CEO
A36: 2
A37: 3
A38: 4
A39: 5
A40: 6
B41: Mỗi task có đúng 1 người R. A là người chịu trách nhiệm cuối cùng về kết quả.
A43: E. TASK TỒN ĐỌNG TỪ TUẦN TRƯỚC
A44: # | B44: Task tồn | C44: Owner | D44: Ưu tiên | E44: Deadline mới | F44: Lý do tồn | H44: Giải pháp
A45: 1 | B45: Setup landing page chiến dịch tháng 10 | C45: B | D45: Cao | E45: 46309 | F45: Chờ designer bàn giao layout | H45: Designer ưu tiên hoàn thành trước 12/10
A46: 2
...

Sheet Marketing Content - Tháng
A1: BÁO CÁO CÔNG VIỆC THÁNG - MARKETING CONTENT
A2: Ô nền vàng: nhập thông tin chung. Ô nền xám: công thức tự tính, không sửa. Dòng số 1 của mỗi bảng là dòng ví dụ, ghi đè hoặc xóa khi dùng.
A4: A. THÔNG TIN CHUNG
B5: Phòng ban | C5: Marketing Content | E5: Tháng/Năm | G5: Tháng 10/2026
B6: Người báo cáo | E6: Người nhận
B7: Hạn nộp | C7: Ngày 3 của tháng sau | E7: Ngày nộp thực tế
A9: B. TỔNG QUAN THÁNG
B10: KPI đạt / tổng KPI | C10: Task hoàn thành | D10: Tỷ lệ đúng hạn | E10: Task tồn đọng | F10: Task hủy / hoãn | G10: Điểm tổng | H10: Xếp loại
B11: =COUNTIF(H15:H22,"Đạt")&" / "&COUNTIF(H15:H22,"?*") -> 1 / 1 | C11: =COUNTA(B37:B48) -> 1 | D11: =IFERROR(COUNTIF(G37:G48,"Đúng hạn")/COUNTIF(G37:G48,"?*"),"") -> 1 | E11: =COUNTA(B52:B57) -> 1 | F11: =COUNTA(B61:B64) -> 1 | G11: =E31 | H11: =E32
A13: C. KPI THÁNG
A14: # | B14: KPI | C14: Đơn vị | D14: Chiều đạt | E14: Target | F14: Thực tế | G14: % HT | H14: Trạng thái | I14: Tháng trước | J14: So tháng trước
A15: 1 | B15: Số bài content | C15: bài | D15: Cao hơn là tốt | E15: 30 | F15: 32 | G15: =IF(OR(E15="",F15=""),"",IF(E15=0,"",F15/E15)) -> 1.0666667 | H15: =IF(G15="","",IF(D15="Thấp hơn là tốt",IF(G15<=1,"Đạt",IF(G15<='Danh mục'!$B$18,"Cần chú ý","Không đạt")),IF(G15>=1,"Đạt",IF(G15>='Danh mục'!$B$17,"Cần chú ý","Không đạt")))) -> Đạt | I15: 28 | J15: =IF(OR(F15="",I15=""),"",F15-I15) -> 4
A16: 2 | B16: Lead | C16: lead | D16: Cao hơn là tốt | G16: =IF(OR(E16="",F16=""),"",IF(E16=0,"",F16/E16)) | H16: =IF(G16="","",IF(D16="Thấp hơn là tốt",IF(G16<=1,"Đạt",IF(G16<='Danh mục'!$B$18,"Cần chú ý","Không đạt")),IF(G16>=1,"Đạt",IF(G16>='Danh mục'!$B$17,"Cần chú ý","Không đạt")))) | J16: =IF(OR(F16="",I16=""),"",F16-I16)
A17: 3 | B17: Chi phí trên mỗi lead (CPL) | C17: VND | D17: Thấp hơn là tốt | G17: =IF(OR(E17="",F17=""),"",IF(E17=0,"",F17/E17)) | H17: =IF(G17="","",IF(D17="Thấp hơn là tốt",IF(G17<=1,"Đạt",IF(G17<='Danh mục'!$B$18,"Cần chú ý","Không đạt")),IF(G17>=1,"Đạt",IF(G17>='Danh mục'!$B$17,"Cần chú ý","Không đạt")))) | J17: =IF(OR(F17="",I17=""),"",F17-I17)
A18: 4 | B18: Reach | C18: lượt | D18: Cao hơn là tốt | G18: =IF(OR(E18="",F18=""),"",IF(E18=0,"",F18/E18)) | H18: =IF(G18="","",IF(D18="Thấp hơn là tốt",IF(G18<=1,"Đạt",IF(G18<='Danh mục'!$B$18,"Cần chú ý","Không đạt")),IF(G18>=1,"Đạt",IF(G18>='Danh mục'!$B$17,"Cần chú ý","Không đạt")))) | J18: =IF(OR(F18="",I18=""),"",F18-I18)
A19: 5 | B19: Tỷ lệ tương tác (ER) | C19: % | D19: Cao hơn là tốt | G19: =IF(OR(E19="",F19=""),"",IF(E19=0,"",F19/E19)) | H19: =IF(G19="","",IF(D19="Thấp hơn là tốt",IF(G19<=1,"Đạt",IF(G19<='Danh mục'!$B$18,"Cần chú ý","Không đạt")),IF(G19>=1,"Đạt",IF(G19>='Danh mục'!$B$17,"Cần chú ý","Không đạt")))) | J19: =IF(OR(F19="",I19=""),"",F19-I19)
A20: 6 | B20: Chi phí quảng cáo so với ngân sách | C20: % | D20: Thấp hơn là tốt | G20: =IF(OR(E20="",F20=""),"",IF(E20=0,"",F20/E20)) | H20: =IF(G20="","",IF(D20="Thấp hơn là tốt",IF(G20<=1,"Đạt",IF(G20<='Danh mục'!$B$18,"Cần chú ý","Không đạt")),IF(G20>=1,"Đạt",IF(G20>='Danh mục'!$B$17,"Cần chú ý","Không đạt")))) | J20: =IF(OR(F20="",I20=""),"",F20-I20)
A21: 7 | G21: =IF(OR(E21="",F21=""),"",IF(E21=0,"",F21/E21)) | H21: =IF(G21="","",IF(D21="Thấp hơn là tốt",IF(G21<=1,"Đạt",IF(G21<='Danh mục'!$B$18,"Cần chú ý","Không đạt")),IF(G21>=1,"Đạt",IF(G21>='Danh mục'!$B$17,"Cần chú ý","Không đạt")))) | J21: =IF(OR(F21="",I21=""),"",F21-I21)
A22: 8 | G22: =IF(OR(E22="",F22=""),"",IF(E22=0,"",F22/E22)) | H22: =IF(G22="","",IF(D22="Thấp hơn là tốt",IF(G22<=1,"Đạt",IF(G22<='Danh mục'!$B$18,"Cần chú ý","Không đạt")),IF(G22>=1,"Đạt",IF(G22>='Danh mục'!$B$17,"Cần chú ý","Không đạt")))) | J22: =IF(OR(F22="",I22=""),"",F22-I22)
A24: D. ĐIỂM SỐ ĐÁNH GIÁ
A25: # | B25: Tiêu chí | C25: Trọng số | D25: Điểm (0-10) | E25: Điểm quy đổi | F25: Căn cứ chấm điểm
A26: 1 | B26: Hoàn thành KPI | C26: 0.5 | E26: =IF(D26="","",C26*D26)
A27: 2 | B27: Chất lượng công việc | C27: 0.2 | E27: =IF(D27="","",C27*D27)
A28: 3 | B28: Đúng deadline | C28: 0.15 | E28: =IF(D28="","",C28*D28)
A29: 4 | B29: Phối hợp | C29: 0.1 | E29: =IF(D29="","",C29*D29)
A30: 5 | B30: Sáng kiến cải tiến | C30: 0.05 | E30: =IF(D30="","",C30*D30)
B31: TỔNG | C31: =SUM(C26:C30) -> 1 | E31: =IF(COUNT(D26:D30)=0,"",SUM(E26:E30)) | F31: =IF(ROUND(C31,4)=1,"Trọng số hợp lệ (tổng 100%)","Tổng trọng số phải bằng 100%") -> Trọng số hợp lệ (tổng 100%)
B32: XẾP LOẠI | E32: =IF(E31="","",IF(E31>='Danh mục'!$B$19,"A",IF(E31>='Danh mục'!$B$20,"B",IF(E31>='Danh mục'!$B$21,"C","D")))) | F32: A (từ 9) / B (từ 7) / C (từ 5) / D (dưới 5). Ngưỡng cấu hình ở sheet Danh mục.
A34: E. CHI TIẾT CÔNG VIỆC THÁNG
B35: E.1. Task hoàn thành
A36: # | B36: Task | C36: Owner | D36: Vai trò | E36: Deadline | F36: Ngày xong | G36: Đúng hạn? | H36: Kết quả
A37: 1 | B37: Campaign tháng 10 | C37: A | D37: Media Buyer | E37: 46315 | F37: 46314 | G37: =IF(OR(E37="",F37=""),"",IF(F37<=E37,"Đúng hạn","Trễ")) -> Đúng hạn | H37: 120 lead
A38: 2 | G38: =IF(OR(E38="",F38=""),"",IF(F38<=E38,"Đúng hạn","Trễ"))
A39: 3 | G39: =IF(OR(E39="",F39=""),"",IF(F39<=E39,"Đúng hạn","Trễ"))
A40: 4 | G40: =IF(OR(E40="",F40=""),"",IF(F40<=E40,"Đúng hạn","Trễ"))
A41: 5 | G41: =IF(OR(E41="",F41=""),"",IF(F41<=E41,"Đúng hạn","Trễ"))
A42: 6 | G42: =IF(OR(E42="",F42=""),"",IF(F42<=E42,"Đúng hạn","Trễ"))
A43: 7 | G43: =IF(OR(E43="",F43=""),"",IF(F43<=E43,"Đúng hạn","Trễ"))
A44: 8 | G44: =IF(OR(E44="",F44=""),"",IF(F44<=E44,"Đúng hạn","Trễ"))
A45: 9 | G45: =IF(OR(E45="",F45=""),"",IF(F45<=E45,"Đúng hạn","Trễ"))
...

Sheet Tài chính Thu mua - Tuần
A1: BÁO CÁO CÔNG VIỆC TUẦN - TÀI CHÍNH - THU MUA
A2: Ô nền vàng: nhập thông tin chung. Ô nền xám: công thức tự tính, không sửa. Dòng số 1 của mỗi bảng là dòng ví dụ, ghi đè hoặc xóa khi dùng.
A4: A. THÔNG TIN CHUNG
B5: Phòng ban | C5: Tài chính - Thu mua | E5: Tuần số | G5: 41
B6: Từ ngày (Thứ 2) | C6: 46300 | E6: Đến ngày (Chủ nhật) | G6: =C6+6 -> 46306
B7: Người báo cáo | E7: Người nhận
B8: Hạn nộp | C8: Thứ 6, 17:00 | E8: Ngày nộp thực tế
A10: B. TỔNG QUAN TUẦN
B11: Tổng task | C11: Done | D11: In Progress | E11: Blocked | F11: Pending | G11: Overdue | H11: % hoàn thành trung bình | I11: Tỷ lệ task Done
B12: =COUNTA(B16:B30) -> 1 | C12: =COUNTIF(F16:F30,"Done") -> 1 | D12: =COUNTIF(F16:F30,"In Progress") -> 0 | E12: =COUNTIF(F16:F30,"Blocked") -> 0 | F12: =COUNTIF(F16:F30,"Pending") -> 0 | G12: =COUNTIF(F16:F30,"Overdue") -> 0 | H12: =IFERROR(AVERAGE(G16:G30),"") -> 1 | I12: =IFERROR(C12/B12,"") -> 1
A14: C. BẢNG CÔNG VIỆC TRONG TUẦN
A15: # | B15: Task | C15: Vai trò | D15: Owner | E15: Deadline | F15: Status | G15: % HT | H15: Kết quả / Ghi chú
A16: 1 | B16: Chốt sổ và đối chiếu công nợ nhà cung cấp | C16: Kế toán công nợ | D16: Cường | E16: 46304 | F16: Done | G16: 1 | H16: Đối chiếu xong 12 nhà cung cấp
A17: 2
A18: 3
A19: 4
A20: 5
A21: 6
A22: 7
A23: 8
A24: 9
A25: 10
A26: 11
A27: 12
A28: 13
... A30: 15
B31: Status: Done (hoàn thành) / In Progress (đang làm) / Blocked (đang vướng) / Pending (chờ xử lý) / Overdue (trễ hạn). Deadline quá hạn mà chưa Done sẽ hiện chữ đỏ.
A33: D. VAI TRÒ VÀ TRÁCH NHIỆM (RACI) - CHO TASK QUAN TRỌNG
A34: # | B34: Task | C34: R - Người làm | D34: A - Người duyệt / chịu trách nhiệm cuối | E34: C - Người tư vấn | G34: I - Người nhận thông tin | I34: Ghi chú
A35: 1 | B35: Duyệt đề nghị thanh toán | C35: Cường | D35: Cường | E35: Giám đốc tài chính | G35: Phòng đề xuất
A36: 2
A37: 3
A38: 4
A39: 5
A40: 6
B41: Mỗi task có đúng 1 người R. A là người chịu trách nhiệm cuối cùng về kết quả.
A43: E. TASK TỒN ĐỌNG TỪ TUẦN TRƯỚC
A44: # | B44: Task tồn | C44: Owner | D44: Ưu tiên | E44: Deadline mới | F44: Lý do tồn | H44: Giải pháp
A45: 1 | B45: Bổ sung chứng từ thanh toán tháng 9 | C45: B | D45: Cao | E45: 46309 | F45: Thiếu hóa đơn từ nhà cung cấp | H45: Gửi yêu cầu bổ sung, hạn chót 13/10
A46: 2
...

Sheet Tài chính Thu mua - Tháng
A1: BÁO CÁO CÔNG VIỆC THÁNG - TÀI CHÍNH - THU MUA
A2: Ô nền vàng: nhập thông tin chung. Ô nền xám: công thức tự tính, không sửa. Dòng số 1 của mỗi bảng là dòng ví dụ, ghi đè hoặc xóa khi dùng.
A4: A. THÔNG TIN CHUNG
B5: Phòng ban | C5: Tài chính - Thu mua | E5: Tháng/Năm | G5: Tháng 10/2026
B6: Người báo cáo | E6: Người nhận
B7: Hạn nộp | C7: Ngày 3 của tháng sau | E7: Ngày nộp thực tế
A9: B. TỔNG QUAN THÁNG
B10: KPI đạt / tổng KPI | C10: Task hoàn thành | D10: Tỷ lệ đúng hạn | E10: Task tồn đọng | F10: Task hủy / hoãn | G10: Điểm tổng | H10: Xếp loại
B11: =COUNTIF(H15:H22,"Đạt")&" / "&COUNTIF(H15:H22,"?*") -> 1 / 1 | C11: =COUNTA(B37:B48) -> 1 | D11: =IFERROR(COUNTIF(G37:G48,"Đúng hạn")/COUNTIF(G37:G48,"?*"),"") -> 1 | E11: =COUNTA(B52:B57) -> 1 | F11: =COUNTA(B61:B64) -> 1 | G11: =E31 | H11: =E32
A13: C. KPI THÁNG
A14: # | B14: KPI | C14: Đơn vị | D14: Chiều đạt | E14: Target | F14: Thực tế | G14: % HT | H14: Trạng thái | I14: Tháng trước | J14: So tháng trước
A15: 1 | B15: Số PO xử lý | C15: PO | D15: Cao hơn là tốt | E15: 120 | F15: 130 | G15: =IF(OR(E15="",F15=""),"",IF(E15=0,"",F15/E15)) -> 1.0833333 | H15: =IF(G15="","",IF(D15="Thấp hơn là tốt",IF(G15<=1,"Đạt",IF(G15<='Danh mục'!$B$18,"Cần chú ý","Không đạt")),IF(G15>=1,"Đạt",IF(G15>='Danh mục'!$B$17,"Cần chú ý","Không đạt")))) -> Đạt | I15: 115 | J15: =IF(OR(F15="",I15=""),"",F15-I15) -> 15
A16: 2 | B16: Thanh toán nhà cung cấp đúng hạn | C16: % | D16: Cao hơn là tốt | G16: =IF(OR(E16="",F16=""),"",IF(E16=0,"",F16/E16)) | H16: =IF(G16="","",IF(D16="Thấp hơn là tốt",IF(G16<=1,"Đạt",IF(G16<='Danh mục'!$B$18,"Cần chú ý","Không đạt")),IF(G16>=1,"Đạt",IF(G16>='Danh mục'!$B$17,"Cần chú ý","Không đạt")))) | J16: =IF(OR(F16="",I16=""),"",F16-I16)
A17: 3 | B17: Tiết kiệm chi phí thu mua | C17: % | D17: Cao hơn là tốt | G17: =IF(OR(E17="",F17=""),"",IF(E17=0,"",F17/E17)) | H17: =IF(G17="","",IF(D17="Thấp hơn là tốt",IF(G17<=1,"Đạt",IF(G17<='Danh mục'!$B$18,"Cần chú ý","Không đạt")),IF(G17>=1,"Đạt",IF(G17>='Danh mục'!$B$17,"Cần chú ý","Không đạt")))) | J17: =IF(OR(F17="",I17=""),"",F17-I17)
A18: 4 | B18: Chênh lệch so với ngân sách | C18: % | D18: Thấp hơn là tốt | G18: =IF(OR(E18="",F18=""),"",IF(E18=0,"",F18/E18)) | H18: =IF(G18="","",IF(D18="Thấp hơn là tốt",IF(G18<=1,"Đạt",IF(G18<='Danh mục'!$B$18,"Cần chú ý","Không đạt")),IF(G18>=1,"Đạt",IF(G18>='Danh mục'!$B$17,"Cần chú ý","Không đạt")))) | J18: =IF(OR(F18="",I18=""),"",F18-I18)
A19: 5 | B19: DSO | C19: ngày | D19: Thấp hơn là tốt | G19: =IF(OR(E19="",F19=""),"",IF(E19=0,"",F19/E19)) | H19: =IF(G19="","",IF(D19="Thấp hơn là tốt",IF(G19<=1,"Đạt",IF(G19<='Danh mục'!$B$18,"Cần chú ý","Không đạt")),IF(G19>=1,"Đạt",IF(G19>='Danh mục'!$B$17,"Cần chú ý","Không đạt")))) | J19: =IF(OR(F19="",I19=""),"",F19-I19)
A20: 6 | B20: Số ngày trễ chốt sổ | C20: ngày | D20: Thấp hơn là tốt | G20: =IF(OR(E20="",F20=""),"",IF(E20=0,"",F20/E20)) | H20: =IF(G20="","",IF(D20="Thấp hơn là tốt",IF(G20<=1,"Đạt",IF(G20<='Danh mục'!$B$18,"Cần chú ý","Không đạt")),IF(G20>=1,"Đạt",IF(G20>='Danh mục'!$B$17,"Cần chú ý","Không đạt")))) | J20: =IF(OR(F20="",I20=""),"",F20-I20)
A21: 7 | G21: =IF(OR(E21="",F21=""),"",IF(E21=0,"",F21/E21)) | H21: =IF(G21="","",IF(D21="Thấp hơn là tốt",IF(G21<=1,"Đạt",IF(G21<='Danh mục'!$B$18,"Cần chú ý","Không đạt")),IF(G21>=1,"Đạt",IF(G21>='Danh mục'!$B$17,"Cần chú ý","Không đạt")))) | J21: =IF(OR(F21="",I21=""),"",F21-I21)
A22: 8 | G22: =IF(OR(E22="",F22=""),"",IF(E22=0,"",F22/E22)) | H22: =IF(G22="","",IF(D22="Thấp hơn là tốt",IF(G22<=1,"Đạt",IF(G22<='Danh mục'!$B$18,"Cần chú ý","Không đạt")),IF(G22>=1,"Đạt",IF(G22>='Danh mục'!$B$17,"Cần chú ý","Không đạt")))) | J22: =IF(OR(F22="",I22=""),"",F22-I22)
A24: D. ĐIỂM SỐ ĐÁNH GIÁ
A25: # | B25: Tiêu chí | C25: Trọng số | D25: Điểm (0-10) | E25: Điểm quy đổi | F25: Căn cứ chấm điểm
A26: 1 | B26: Hoàn thành KPI | C26: 0.5 | E26: =IF(D26="","",C26*D26)
A27: 2 | B27: Chất lượng công việc | C27: 0.2 | E27: =IF(D27="","",C27*D27)
A28: 3 | B28: Đúng deadline | C28: 0.15 | E28: =IF(D28="","",C28*D28)
A29: 4 | B29: Phối hợp | C29: 0.1 | E29: =IF(D29="","",C29*D29)
A30: 5 | B30: Sáng kiến cải tiến | C30: 0.05 | E30: =IF(D30="","",C30*D30)
B31: TỔNG | C31: =SUM(C26:C30) -> 1 | E31: =IF(COUNT(D26:D30)=0,"",SUM(E26:E30)) | F31: =IF(ROUND(C31,4)=1,"Trọng số hợp lệ (tổng 100%)","Tổng trọng số phải bằng 100%") -> Trọng số hợp lệ (tổng 100%)
B32: XẾP LOẠI | E32: =IF(E31="","",IF(E31>='Danh mục'!$B$19,"A",IF(E31>='Danh mục'!$B$20,"B",IF(E31>='Danh mục'!$B$21,"C","D")))) | F32: A (từ 9) / B (từ 7) / C (từ 5) / D (dưới 5). Ngưỡng cấu hình ở sheet Danh mục.
A34: E. CHI TIẾT CÔNG VIỆC THÁNG
B35: E.1. Task hoàn thành
A36: # | B36: Task | C36: Owner | D36: Vai trò | E36: Deadline | F36: Ngày xong | G36: Đúng hạn? | H36: Kết quả
A37: 1 | B37: Nộp báo cáo thuế tháng 9 | C37: A | D37: Kế toán tổng hợp | E37: 46315 | F37: 46315 | G37: =IF(OR(E37="",F37=""),"",IF(F37<=E37,"Đúng hạn","Trễ")) -> Đúng hạn | H37: Nộp đúng hạn
A38: 2 | G38: =IF(OR(E38="",F38=""),"",IF(F38<=E38,"Đúng hạn","Trễ"))
A39: 3 | G39: =IF(OR(E39="",F39=""),"",IF(F39<=E39,"Đúng hạn","Trễ"))
A40: 4 | G40: =IF(OR(E40="",F40=""),"",IF(F40<=E40,"Đúng hạn","Trễ"))
A41: 5 | G41: =IF(OR(E41="",F41=""),"",IF(F41<=E41,"Đúng hạn","Trễ"))
A42: 6 | G42: =IF(OR(E42="",F42=""),"",IF(F42<=E42,"Đúng hạn","Trễ"))
A43: 7 | G43: =IF(OR(E43="",F43=""),"",IF(F43<=E43,"Đúng hạn","Trễ"))
A44: 8 | G44: =IF(OR(E44="",F44=""),"",IF(F44<=E44,"Đúng hạn","Trễ"))
A45: 9 | G45: =IF(OR(E45="",F45=""),"",IF(F45<=E45,"Đúng hạn","Trễ"))
...

Sheet Program Event - Tuần
A1: BÁO CÁO CÔNG VIỆC TUẦN - PROGRAM EVENT
A2: Ô nền vàng: nhập thông tin chung. Ô nền xám: công thức tự tính, không sửa. Dòng số 1 của mỗi bảng là dòng ví dụ, ghi đè hoặc xóa khi dùng.
A4: A. THÔNG TIN CHUNG
B5: Phòng ban | C5: Program Event | E5: Tuần số | G5: 41
B6: Từ ngày (Thứ 2) | C6: 46300 | E6: Đến ngày (Chủ nhật) | G6: =C6+6 -> 46306
B7: Người báo cáo | E7: Người nhận
B8: Hạn nộp | C8: Thứ 6, 17:00 | E8: Ngày nộp thực tế
A10: B. TỔNG QUAN TUẦN
B11: Tổng task | C11: Done | D11: In Progress | E11: Blocked | F11: Pending | G11: Overdue | H11: % hoàn thành trung bình | I11: Tỷ lệ task Done
B12: =COUNTA(B16:B30) -> 1 | C12: =COUNTIF(F16:F30,"Done") -> 1 | D12: =COUNTIF(F16:F30,"In Progress") -> 0 | E12: =COUNTIF(F16:F30,"Blocked") -> 0 | F12: =COUNTIF(F16:F30,"Pending") -> 0 | G12: =COUNTIF(F16:F30,"Overdue") -> 0 | H12: =IFERROR(AVERAGE(G16:G30),"") -> 1 | I12: =IFERROR(C12/B12,"") -> 1
A14: C. BẢNG CÔNG VIỆC TRONG TUẦN
A15: # | B15: Task | C15: Vai trò | D15: Owner | E15: Deadline | F15: Status | G15: % HT | H15: Kết quả / Ghi chú
A16: 1 | B16: Chốt kịch bản và timeline sự kiện ra mắt sản phẩm | C16: Producer | D16: A | E16: 46303 | F16: Done | G16: 1 | H16: Khách hàng đã duyệt kịch bản
A17: 2
A18: 3
A19: 4
A20: 5
A21: 6
A22: 7
A23: 8
A24: 9
A25: 10
A26: 11
A27: 12
A28: 13
... A30: 15
B31: Status: Done (hoàn thành) / In Progress (đang làm) / Blocked (đang vướng) / Pending (chờ xử lý) / Overdue (trễ hạn). Deadline quá hạn mà chưa Done sẽ hiện chữ đỏ.
A33: D. VAI TRÒ VÀ TRÁCH NHIỆM (RACI) - CHO TASK QUAN TRỌNG
A34: # | B34: Task | C34: R - Người làm | D34: A - Người duyệt / chịu trách nhiệm cuối | E34: C - Người tư vấn | G34: I - Người nhận thông tin | I34: Ghi chú
A35: 1 | B35: Setup sân khấu | C35: A | D35: A | E35: Vendor Coordinator | G35: Khách hàng
A36: 2
A37: 3
A38: 4
A39: 5
A40: 6
B41: Mỗi task có đúng 1 người R. A là người chịu trách nhiệm cuối cùng về kết quả.
A43: E. TASK TỒN ĐỌNG TỪ TUẦN TRƯỚC
A44: # | B44: Task tồn | C44: Owner | D44: Ưu tiên | E44: Deadline mới | F44: Lý do tồn | H44: Giải pháp
A45: 1 | B45: Xác nhận hợp đồng nhà cung cấp âm thanh ánh sáng | C45: B | D45: Cao | E45: 46307 | F45: Vendor chưa gửi báo giá cuối | H45: Escalate lên quản lý vendor, hạn chót 11/10
A46: 2
...

Sheet Program Event - Tháng
A1: BÁO CÁO CÔNG VIỆC THÁNG - PROGRAM EVENT
A2: Ô nền vàng: nhập thông tin chung. Ô nền xám: công thức tự tính, không sửa. Dòng số 1 của mỗi bảng là dòng ví dụ, ghi đè hoặc xóa khi dùng.
A4: A. THÔNG TIN CHUNG
B5: Phòng ban | C5: Program Event | E5: Tháng/Năm | G5: Tháng 10/2026
B6: Người báo cáo | E6: Người nhận
B7: Hạn nộp | C7: Ngày 3 của tháng sau | E7: Ngày nộp thực tế
A9: B. TỔNG QUAN THÁNG
B10: KPI đạt / tổng KPI | C10: Task hoàn thành | D10: Tỷ lệ đúng hạn | E10: Task tồn đọng | F10: Task hủy / hoãn | G10: Điểm tổng | H10: Xếp loại
B11: =COUNTIF(H15:H22,"Đạt")&" / "&COUNTIF(H15:H22,"?*") -> 1 / 1 | C11: =COUNTA(B37:B48) -> 1 | D11: =IFERROR(COUNTIF(G37:G48,"Đúng hạn")/COUNTIF(G37:G48,"?*"),"") -> 1 | E11: =COUNTA(B52:B57) -> 1 | F11: =COUNTA(B61:B64) -> 1 | G11: =E31 | H11: =E32
A13: C. KPI THÁNG
A14: # | B14: KPI | C14: Đơn vị | D14: Chiều đạt | E14: Target | F14: Thực tế | G14: % HT | H14: Trạng thái | I14: Tháng trước | J14: So tháng trước
A15: 1 | B15: Số sự kiện tổ chức | C15: sự kiện | D15: Cao hơn là tốt | E15: 3 | F15: 3 | G15: =IF(OR(E15="",F15=""),"",IF(E15=0,"",F15/E15)) -> 1 | H15: =IF(G15="","",IF(D15="Thấp hơn là tốt",IF(G15<=1,"Đạt",IF(G15<='Danh mục'!$B$18,"Cần chú ý","Không đạt")),IF(G15>=1,"Đạt",IF(G15>='Danh mục'!$B$17,"Cần chú ý","Không đạt")))) -> Đạt | I15: 2 | J15: =IF(OR(F15="",I15=""),"",F15-I15) -> 1
A16: 2 | B16: Mức độ hoàn thành milestone | C16: % | D16: Cao hơn là tốt | G16: =IF(OR(E16="",F16=""),"",IF(E16=0,"",F16/E16)) | H16: =IF(G16="","",IF(D16="Thấp hơn là tốt",IF(G16<=1,"Đạt",IF(G16<='Danh mục'!$B$18,"Cần chú ý","Không đạt")),IF(G16>=1,"Đạt",IF(G16>='Danh mục'!$B$17,"Cần chú ý","Không đạt")))) | J16: =IF(OR(F16="",I16=""),"",F16-I16)
A17: 3 | B17: NPS | C17: điểm | D17: Cao hơn là tốt | G17: =IF(OR(E17="",F17=""),"",IF(E17=0,"",F17/E17)) | H17: =IF(G17="","",IF(D17="Thấp hơn là tốt",IF(G17<=1,"Đạt",IF(G17<='Danh mục'!$B$18,"Cần chú ý","Không đạt")),IF(G17>=1,"Đạt",IF(G17>='Danh mục'!$B$17,"Cần chú ý","Không đạt")))) | J17: =IF(OR(F17="",I17=""),"",F17-I17)
A18: 4 | B18: ROI sự kiện | C18: % | D18: Cao hơn là tốt | G18: =IF(OR(E18="",F18=""),"",IF(E18=0,"",F18/E18)) | H18: =IF(G18="","",IF(D18="Thấp hơn là tốt",IF(G18<=1,"Đạt",IF(G18<='Danh mục'!$B$18,"Cần chú ý","Không đạt")),IF(G18>=1,"Đạt",IF(G18>='Danh mục'!$B$17,"Cần chú ý","Không đạt")))) | J18: =IF(OR(F18="",I18=""),"",F18-I18)
A19: 5 | B19: Chi phí thực tế so với ngân sách | C19: % | D19: Thấp hơn là tốt | G19: =IF(OR(E19="",F19=""),"",IF(E19=0,"",F19/E19)) | H19: =IF(G19="","",IF(D19="Thấp hơn là tốt",IF(G19<=1,"Đạt",IF(G19<='Danh mục'!$B$18,"Cần chú ý","Không đạt")),IF(G19>=1,"Đạt",IF(G19>='Danh mục'!$B$17,"Cần chú ý","Không đạt")))) | J19: =IF(OR(F19="",I19=""),"",F19-I19)
A20: 6 | B20: Số sự cố | C20: sự cố | D20: Thấp hơn là tốt | G20: =IF(OR(E20="",F20=""),"",IF(E20=0,"",F20/E20)) | H20: =IF(G20="","",IF(D20="Thấp hơn là tốt",IF(G20<=1,"Đạt",IF(G20<='Danh mục'!$B$18,"Cần chú ý","Không đạt")),IF(G20>=1,"Đạt",IF(G20>='Danh mục'!$B$17,"Cần chú ý","Không đạt")))) | J20: =IF(OR(F20="",I20=""),"",F20-I20)
A21: 7 | G21: =IF(OR(E21="",F21=""),"",IF(E21=0,"",F21/E21)) | H21: =IF(G21="","",IF(D21="Thấp hơn là tốt",IF(G21<=1,"Đạt",IF(G21<='Danh mục'!$B$18,"Cần chú ý","Không đạt")),IF(G21>=1,"Đạt",IF(G21>='Danh mục'!$B$17,"Cần chú ý","Không đạt")))) | J21: =IF(OR(F21="",I21=""),"",F21-I21)
A22: 8 | G22: =IF(OR(E22="",F22=""),"",IF(E22=0,"",F22/E22)) | H22: =IF(G22="","",IF(D22="Thấp hơn là tốt",IF(G22<=1,"Đạt",IF(G22<='Danh mục'!$B$18,"Cần chú ý","Không đạt")),IF(G22>=1,"Đạt",IF(G22>='Danh mục'!$B$17,"Cần chú ý","Không đạt")))) | J22: =IF(OR(F22="",I22=""),"",F22-I22)
A24: D. ĐIỂM SỐ ĐÁNH GIÁ
A25: # | B25: Tiêu chí | C25: Trọng số | D25: Điểm (0-10) | E25: Điểm quy đổi | F25: Căn cứ chấm điểm
A26: 1 | B26: Hoàn thành KPI | C26: 0.5 | E26: =IF(D26="","",C26*D26)
A27: 2 | B27: Chất lượng công việc | C27: 0.2 | E27: =IF(D27="","",C27*D27)
A28: 3 | B28: Đúng deadline | C28: 0.15 | E28: =IF(D28="","",C28*D28)
A29: 4 | B29: Phối hợp | C29: 0.1 | E29: =IF(D29="","",C29*D29)
A30: 5 | B30: Sáng kiến cải tiến | C30: 0.05 | E30: =IF(D30="","",C30*D30)
B31: TỔNG | C31: =SUM(C26:C30) -> 1 | E31: =IF(COUNT(D26:D30)=0,"",SUM(E26:E30)) | F31: =IF(ROUND(C31,4)=1,"Trọng số hợp lệ (tổng 100%)","Tổng trọng số phải bằng 100%") -> Trọng số hợp lệ (tổng 100%)
B32: XẾP LOẠI | E32: =IF(E31="","",IF(E31>='Danh mục'!$B$19,"A",IF(E31>='Danh mục'!$B$20,"B",IF(E31>='Danh mục'!$B$21,"C","D")))) | F32: A (từ 9) / B (từ 7) / C (từ 5) / D (dưới 5). Ngưỡng cấu hình ở sheet Danh mục.
A34: E. CHI TIẾT CÔNG VIỆC THÁNG
B35: E.1. Task hoàn thành
A36: # | B36: Task | C36: Owner | D36: Vai trò | E36: Deadline | F36: Ngày xong | G36: Đúng hạn? | H36: Kết quả
A37: 1 | B37: Tổ chức sự kiện ra mắt sản phẩm | C37: A | D37: Event Executive | E37: 46320 | F37: 46320 | G37: =IF(OR(E37="",F37=""),"",IF(F37<=E37,"Đúng hạn","Trễ")) -> Đúng hạn | H37: Đủ 300 khách tham dự
A38: 2 | G38: =IF(OR(E38="",F38=""),"",IF(F38<=E38,"Đúng hạn","Trễ"))
A39: 3 | G39: =IF(OR(E39="",F39=""),"",IF(F39<=E39,"Đúng hạn","Trễ"))
A40: 4 | G40: =IF(OR(E40="",F40=""),"",IF(F40<=E40,"Đúng hạn","Trễ"))
A41: 5 | G41: =IF(OR(E41="",F41=""),"",IF(F41<=E41,"Đúng hạn","Trễ"))
A42: 6 | G42: =IF(OR(E42="",F42=""),"",IF(F42<=E42,"Đúng hạn","Trễ"))
A43: 7 | G43: =IF(OR(E43="",F43=""),"",IF(F43<=E43,"Đúng hạn","Trễ"))
A44: 8 | G44: =IF(OR(E44="",F44=""),"",IF(F44<=E44,"Đúng hạn","Trễ"))
A45: 9 | G45: =IF(OR(E45="",F45=""),"",IF(F45<=E45,"Đúng hạn","Trễ"))
...

Sheet Nhân sự - Tuần
A1: BÁO CÁO CÔNG VIỆC TUẦN - NHÂN SỰ
A2: Ô nền vàng: nhập thông tin chung. Ô nền xám: công thức tự tính, không sửa. Dòng số 1 của mỗi bảng là dòng ví dụ, ghi đè hoặc xóa khi dùng.
A4: A. THÔNG TIN CHUNG
B5: Phòng ban | C5: Nhân sự | E5: Tuần số | G5: 41
B6: Từ ngày (Thứ 2) | C6: 46300 | E6: Đến ngày (Chủ nhật) | G6: =C6+6 -> 46306
B7: Người báo cáo | E7: Người nhận
B8: Hạn nộp | C8: Thứ 6, 17:00 | E8: Ngày nộp thực tế
A10: B. TỔNG QUAN TUẦN
B11: Tổng task | C11: Done | D11: In Progress | E11: Blocked | F11: Pending | G11: Overdue | H11: % hoàn thành trung bình | I11: Tỷ lệ task Done
B12: =COUNTA(B16:B30) -> 1 | C12: =COUNTIF(F16:F30,"Done") -> 1 | D12: =COUNTIF(F16:F30,"In Progress") -> 0 | E12: =COUNTIF(F16:F30,"Blocked") -> 0 | F12: =COUNTIF(F16:F30,"Pending") -> 0 | G12: =COUNTIF(F16:F30,"Overdue") -> 0 | H12: =IFERROR(AVERAGE(G16:G30),"") -> 1 | I12: =IFERROR(C12/B12,"") -> 1
A14: C. BẢNG CÔNG VIỆC TRONG TUẦN
A15: # | B15: Task | C15: Vai trò | D15: Owner | E15: Deadline | F15: Status | G15: % HT | H15: Kết quả / Ghi chú
A16: 1 | B16: Sàng lọc CV cho vị trí Sales Executive | C16: Recruiter | D16: A | E16: 46303 | F16: Done | G16: 1 | H16: Sàng lọc 60 CV, chọn 15 ứng viên
A17: 2
A18: 3
A19: 4
A20: 5
A21: 6
A22: 7
A23: 8
A24: 9
A25: 10
A26: 11
A27: 12
A28: 13
... A30: 15
B31: Status: Done (hoàn thành) / In Progress (đang làm) / Blocked (đang vướng) / Pending (chờ xử lý) / Overdue (trễ hạn). Deadline quá hạn mà chưa Done sẽ hiện chữ đỏ.
A33: D. VAI TRÒ VÀ TRÁCH NHIỆM (RACI) - CHO TASK QUAN TRỌNG
A34: # | B34: Task | C34: R - Người làm | D34: A - Người duyệt / chịu trách nhiệm cuối | E34: C - Người tư vấn | G34: I - Người nhận thông tin | I34: Ghi chú
A35: 1 | B35: Phỏng vấn ứng viên | C35: Recruiter | D35: Trưởng phòng Nhân sự | E35: Trưởng bộ phận cần tuyển | G35: CEO
A36: 2
A37: 3
A38: 4
A39: 5
A40: 6
B41: Mỗi task có đúng 1 người R. A là người chịu trách nhiệm cuối cùng về kết quả.
A43: E. TASK TỒN ĐỌNG TỪ TUẦN TRƯỚC
A44: # | B44: Task tồn | C44: Owner | D44: Ưu tiên | E44: Deadline mới | F44: Lý do tồn | H44: Giải pháp
A45: 1 | B45: Hoàn thiện hồ sơ nhân viên mới | C45: B | D45: Trung bình | E45: 46308 | F45: Thiếu giấy tờ từ nhân viên | H45: Nhắc nhân viên nộp, hạn chót 12/10
A46: 2
...

Sheet Nhân sự - Tháng
A1: BÁO CÁO CÔNG VIỆC THÁNG - NHÂN SỰ
A2: Ô nền vàng: nhập thông tin chung. Ô nền xám: công thức tự tính, không sửa. Dòng số 1 của mỗi bảng là dòng ví dụ, ghi đè hoặc xóa khi dùng.
A4: A. THÔNG TIN CHUNG
B5: Phòng ban | C5: Nhân sự | E5: Tháng/Năm | G5: Tháng 10/2026
B6: Người báo cáo | E6: Người nhận
B7: Hạn nộp | C7: Ngày 3 của tháng sau | E7: Ngày nộp thực tế
A9: B. TỔNG QUAN THÁNG
B10: KPI đạt / tổng KPI | C10: Task hoàn thành | D10: Tỷ lệ đúng hạn | E10: Task tồn đọng | F10: Task hủy / hoãn | G10: Điểm tổng | H10: Xếp loại
B11: =COUNTIF(H15:H22,"Đạt")&" / "&COUNTIF(H15:H22,"?*") -> 0 / 1 | C11: =COUNTA(B37:B48) -> 1 | D11: =IFERROR(COUNTIF(G37:G48,"Đúng hạn")/COUNTIF(G37:G48,"?*"),"") -> 1 | E11: =COUNTA(B52:B57) -> 1 | F11: =COUNTA(B61:B64) -> 1 | G11: =E31 | H11: =E32
A13: C. KPI THÁNG
A14: # | B14: KPI | C14: Đơn vị | D14: Chiều đạt | E14: Target | F14: Thực tế | G14: % HT | H14: Trạng thái | I14: Tháng trước | J14: So tháng trước
A15: 1 | B15: Số vị trí tuyển đủ so với kế hoạch | C15: % | D15: Cao hơn là tốt | E15: 100 | F15: 85 | G15: =IF(OR(E15="",F15=""),"",IF(E15=0,"",F15/E15)) -> 0.85 | H15: =IF(G15="","",IF(D15="Thấp hơn là tốt",IF(G15<=1,"Đạt",IF(G15<='Danh mục'!$B$18,"Cần chú ý","Không đạt")),IF(G15>=1,"Đạt",IF(G15>='Danh mục'!$B$17,"Cần chú ý","Không đạt")))) -> Cần chú ý | I15: 70 | J15: =IF(OR(F15="",I15=""),"",F15-I15) -> 15
A16: 2 | B16: Time-to-hire | C16: ngày | D16: Thấp hơn là tốt | G16: =IF(OR(E16="",F16=""),"",IF(E16=0,"",F16/E16)) | H16: =IF(G16="","",IF(D16="Thấp hơn là tốt",IF(G16<=1,"Đạt",IF(G16<='Danh mục'!$B$18,"Cần chú ý","Không đạt")),IF(G16>=1,"Đạt",IF(G16>='Danh mục'!$B$17,"Cần chú ý","Không đạt")))) | J16: =IF(OR(F16="",I16=""),"",F16-I16)
A17: 3 | B17: eNPS | C17: điểm | D17: Cao hơn là tốt | G17: =IF(OR(E17="",F17=""),"",IF(E17=0,"",F17/E17)) | H17: =IF(G17="","",IF(D17="Thấp hơn là tốt",IF(G17<=1,"Đạt",IF(G17<='Danh mục'!$B$18,"Cần chú ý","Không đạt")),IF(G17>=1,"Đạt",IF(G17>='Danh mục'!$B$17,"Cần chú ý","Không đạt")))) | J17: =IF(OR(F17="",I17=""),"",F17-I17)
A18: 4 | B18: Tỷ lệ nghỉ việc | C18: % | D18: Thấp hơn là tốt | G18: =IF(OR(E18="",F18=""),"",IF(E18=0,"",F18/E18)) | H18: =IF(G18="","",IF(D18="Thấp hơn là tốt",IF(G18<=1,"Đạt",IF(G18<='Danh mục'!$B$18,"Cần chú ý","Không đạt")),IF(G18>=1,"Đạt",IF(G18>='Danh mục'!$B$17,"Cần chú ý","Không đạt")))) | J18: =IF(OR(F18="",I18=""),"",F18-I18)
A19: 5 | B19: Giờ đào tạo bình quân mỗi người | C19: giờ | D19: Cao hơn là tốt | G19: =IF(OR(E19="",F19=""),"",IF(E19=0,"",F19/E19)) | H19: =IF(G19="","",IF(D19="Thấp hơn là tốt",IF(G19<=1,"Đạt",IF(G19<='Danh mục'!$B$18,"Cần chú ý","Không đạt")),IF(G19>=1,"Đạt",IF(G19>='Danh mục'!$B$17,"Cần chú ý","Không đạt")))) | J19: =IF(OR(F19="",I19=""),"",F19-I19)
A20: 6 | B20: Lương chi trả đúng hạn | C20: % | D20: Cao hơn là tốt | G20: =IF(OR(E20="",F20=""),"",IF(E20=0,"",F20/E20)) | H20: =IF(G20="","",IF(D20="Thấp hơn là tốt",IF(G20<=1,"Đạt",IF(G20<='Danh mục'!$B$18,"Cần chú ý","Không đạt")),IF(G20>=1,"Đạt",IF(G20>='Danh mục'!$B$17,"Cần chú ý","Không đạt")))) | J20: =IF(OR(F20="",I20=""),"",F20-I20)
A21: 7 | G21: =IF(OR(E21="",F21=""),"",IF(E21=0,"",F21/E21)) | H21: =IF(G21="","",IF(D21="Thấp hơn là tốt",IF(G21<=1,"Đạt",IF(G21<='Danh mục'!$B$18,"Cần chú ý","Không đạt")),IF(G21>=1,"Đạt",IF(G21>='Danh mục'!$B$17,"Cần chú ý","Không đạt")))) | J21: =IF(OR(F21="",I21=""),"",F21-I21)
A22: 8 | G22: =IF(OR(E22="",F22=""),"",IF(E22=0,"",F22/E22)) | H22: =IF(G22="","",IF(D22="Thấp hơn là tốt",IF(G22<=1,"Đạt",IF(G22<='Danh mục'!$B$18,"Cần chú ý","Không đạt")),IF(G22>=1,"Đạt",IF(G22>='Danh mục'!$B$17,"Cần chú ý","Không đạt")))) | J22: =IF(OR(F22="",I22=""),"",F22-I22)
A24: D. ĐIỂM SỐ ĐÁNH GIÁ
A25: # | B25: Tiêu chí | C25: Trọng số | D25: Điểm (0-10) | E25: Điểm quy đổi | F25: Căn cứ chấm điểm
A26: 1 | B26: Hoàn thành KPI | C26: 0.5 | E26: =IF(D26="","",C26*D26)
A27: 2 | B27: Chất lượng công việc | C27: 0.2 | E27: =IF(D27="","",C27*D27)
A28: 3 | B28: Đúng deadline | C28: 0.15 | E28: =IF(D28="","",C28*D28)
A29: 4 | B29: Phối hợp | C29: 0.1 | E29: =IF(D29="","",C29*D29)
A30: 5 | B30: Sáng kiến cải tiến | C30: 0.05 | E30: =IF(D30="","",C30*D30)
B31: TỔNG | C31: =SUM(C26:C30) -> 1 | E31: =IF(COUNT(D26:D30)=0,"",SUM(E26:E30)) | F31: =IF(ROUND(C31,4)=1,"Trọng số hợp lệ (tổng 100%)","Tổng trọng số phải bằng 100%") -> Trọng số hợp lệ (tổng 100%)
B32: XẾP LOẠI | E32: =IF(E31="","",IF(E31>='Danh mục'!$B$19,"A",IF(E31>='Danh mục'!$B$20,"B",IF(E31>='Danh mục'!$B$21,"C","D")))) | F32: A (từ 9) / B (từ 7) / C (từ 5) / D (dưới 5). Ngưỡng cấu hình ở sheet Danh mục.
A34: E. CHI TIẾT CÔNG VIỆC THÁNG
B35: E.1. Task hoàn thành
A36: # | B36: Task | C36: Owner | D36: Vai trò | E36: Deadline | F36: Ngày xong | G36: Đúng hạn? | H36: Kết quả
A37: 1 | B37: Chốt bảng lương tháng 9 | C37: C | D37: C&B | E37: 46300 | F37: 46299 | G37: =IF(OR(E37="",F37=""),"",IF(F37<=E37,"Đúng hạn","Trễ")) -> Đúng hạn | H37: Chi trả đúng hạn
A38: 2 | G38: =IF(OR(E38="",F38=""),"",IF(F38<=E38,"Đúng hạn","Trễ"))
A39: 3 | G39: =IF(OR(E39="",F39=""),"",IF(F39<=E39,"Đúng hạn","Trễ"))
A40: 4 | G40: =IF(OR(E40="",F40=""),"",IF(F40<=E40,"Đúng hạn","Trễ"))
A41: 5 | G41: =IF(OR(E41="",F41=""),"",IF(F41<=E41,"Đúng hạn","Trễ"))
A42: 6 | G42: =IF(OR(E42="",F42=""),"",IF(F42<=E42,"Đúng hạn","Trễ"))
A43: 7 | G43: =IF(OR(E43="",F43=""),"",IF(F43<=E43,"Đúng hạn","Trễ"))
A44: 8 | G44: =IF(OR(E44="",F44=""),"",IF(F44<=E44,"Đúng hạn","Trễ"))
A45: 9 | G45: =IF(OR(E45="",F45=""),"",IF(F45<=E45,"Đúng hạn","Trễ"))
...

Sheet Danh mục
A1: DANH MỤC DÙNG CHUNG (nguồn của các danh sách chọn và ngưỡng đánh giá)
A4: Status | B4: Ý nghĩa | D4: Ưu tiên | E4: Ý nghĩa | G4: Chiều đạt KPI | I4: Loại điều chỉnh | K4: Vai trò - Marketing Content | L4: Vai trò - Tài chính Thu mua | M4: Vai trò - Program Event | N4: Vai trò - Nhân sự | O4: Danh sách owner
A5: Done | B5: Hoàn thành | D5: Cao | E5: Ảnh hưởng KPI, xong trong tuần | G5: Cao hơn là tốt | I5: Hủy | K5: Content Writer | L5: Kế toán tổng hợp | M5: Event Executive | N5: Recruiter | O5: Cường
A6: In Progress | B6: Đang làm | D6: Trung bình | E6: Xong trong 1-2 tuần | G6: Thấp hơn là tốt | I6: Hoãn | K6: Designer | L6: Kế toán thanh toán | M6: Producer | N6: HRBP | O6: Minh
A7: Blocked | B7: Đang vướng, cần hỗ trợ | D7: Thấp | E7: Có thể dời | K7: Video Editor | L7: Kế toán công nợ | M7: Vendor Coordinator | N7: C&B | O7: Hân
A8: Pending | B8: Chờ xử lý | K8: Media Buyer | L8: Thu mua | M8: Kỹ thuật sân khấu | N8: L&D | O8: Yến
A9: Overdue | B9: Trễ hạn | K9: SEO Executive | L9: Thủ quỹ | M9: Project Lead | N9: HR Admin | O9: Hảo
K10: Social Media | L10: Kế toán trưởng | M10: Event Manager | N10: Trưởng phòng Nhân sự | O10: Ánh
K11: Marketing Lead | L11: Giám đốc tài chính
A15: NGƯỠNG ĐÁNH GIÁ (ô nền vàng, chữ xanh là giá trị có thể chỉnh)
A16: Tham số | B16: Giá trị
A17: KPI cao hơn là tốt: Cần chú ý khi %HT từ | B17: 0.8
A18: KPI thấp hơn là tốt: Cần chú ý khi %HT đến | B18: 1.2
A19: Xếp loại A khi điểm tổng từ | B19: 9
A20: Xếp loại B khi điểm tổng từ | B20: 7
A21: Xếp loại C khi điểm tổng từ | B21: 5
A22: Dưới ngưỡng C là xếp loại D. KPI cao hơn là tốt: %HT từ 100% là Đạt, dưới ngưỡng cần chú ý là Không đạt. KPI thấp hơn là tốt: %HT đến 100% là Đạt, vượt ngưỡng cần chú ý là Không đạt.
